<mujoco model="brainco_revo2_righthand_urdf">
  <compiler angle="radian" meshdir="../meshes"/>

  <asset>
    <mesh name="right_base_link" content_type="model/stl" file="revo2_right_hand/right_base_link.STL"/>
    <mesh name="right_thumb_metacarpal_link" content_type="model/stl" file="revo2_right_hand/right_thumb_metacarpal_link.STL"/>
    <mesh name="right_thumb_proximal_link" content_type="model/stl" file="revo2_right_hand/right_thumb_proximal_link.STL"/>
    <mesh name="right_thumb_distal_link" content_type="model/stl" file="revo2_right_hand/right_thumb_distal_link.STL"/>
    <mesh name="right_thumb_touch_link" content_type="model/stl" file="revo2_right_hand/right_thumb_touch_link.STL"/>
    <mesh name="right_index_proximal_link" content_type="model/stl" file="revo2_right_hand/right_index_proximal_link.STL"/>
    <mesh name="right_index_distal_link" content_type="model/stl" file="revo2_right_hand/right_index_distal_link.STL"/>
    <mesh name="right_index_touch_link" content_type="model/stl" file="revo2_right_hand/right_index_touch_link.STL"/>
    <mesh name="right_middle_proximal_link" content_type="model/stl" file="revo2_right_hand/right_middle_proximal_link.STL"/>
    <mesh name="right_middle_distal_link" content_type="model/stl" file="revo2_right_hand/right_middle_distal_link.STL"/>
    <mesh name="right_middle_touch_link" content_type="model/stl" file="revo2_right_hand/right_middle_touch_link.STL"/>
    <mesh name="right_ring_proximal_link" content_type="model/stl" file="revo2_right_hand/right_ring_proximal_link.STL"/>
    <mesh name="right_ring_distal_link" content_type="model/stl" file="revo2_right_hand/right_ring_distal_link.STL"/>
    <mesh name="right_ring_touch_link" content_type="model/stl" file="revo2_right_hand/right_ring_touch_link.STL"/>
    <mesh name="right_pinky_proximal_link" content_type="model/stl" file="revo2_right_hand/right_pinky_proximal_link.STL"/>
    <mesh name="right_pinky_distal_link" content_type="model/stl" file="revo2_right_hand/right_pinky_distal_link.STL"/>
    <mesh name="right_pinky_touch_link" content_type="model/stl" file="revo2_right_hand/right_pinky_touch_link.STL"/>
  </asset>

  <worldbody>
    <geom type="mesh" rgba="1 1 1 1" mesh="right_base_link"/>
    <body name="right_thumb_metacarpal_link" pos="0.005619 0.019867 0.027825" quat="0.99648 0 0 -0.0838365">
      <inertial pos="1.51106e-05 0.00707243 -0.00420847" quat="0.465075 -0.0302438 0.0586743 0.882807" mass="0.01" diaginertia="1.66115e-07 1.56006e-07 4.9387e-08"/>
      <joint name="right_thumb_metacarpal_joint" pos="0 0 0" axis="0 0 -1" range="0 1.57" actuatorfrcrange="-0.5 0.5"/>
      <geom type="mesh" rgba="1 1 1 1" mesh="right_thumb_metacarpal_link"/>
      <body name="right_thumb_proximal_link" pos="0 0.014227 0" quat="0.986557 0.0765206 0.124804 0.0726253">
        <inertial pos="-4.6972e-07 0.0277015 -0.00202656" quat="0.496496 0.503512 -0.503514 0.496429" mass="0.05" diaginertia="2.56295e-06 2.40452e-06 5.11916e-07"/>
        <joint name="right_thumb_proximal_joint" pos="0 0 0" axis="1 0 0" range="0 1.03" actuatorfrcrange="-1.1 1.1"/>
        <geom type="mesh" rgba="1 1 1 1" mesh="right_thumb_proximal_link"/>
        <body name="right_thumb_distal_link" pos="0 0.052 0">
          <inertial pos="-0.00229861 0.00826353 -0.00122274" quat="0.508224 0.321185 -0.717381 0.352014" mass="0.012" diaginertia="1.56378e-06 1.44424e-06 2.76577e-07"/>
          <joint name="right_thumb_distal_joint" pos="0 0 0" axis="1 0 0" range="0 1.03" actuatorfrcrange="-1.1 1.1"/>
          <geom type="mesh" rgba="1 1 1 1" mesh="right_thumb_distal_link"/>
          <geom pos="0 0.0137928 0.0076766" quat="0.999443 -0.033369 0 0" type="mesh" rgba="1 1 1 1" mesh="right_thumb_touch_link"/>
        </body>
      </body>
    </body>
    <body name="right_index_proximal_link" pos="-0.0021181 0.029568 0.080876" quat="0.992147 -0.0522807 0.0783652 -0.0822789">
      <inertial pos="-0.00223495 3.15875e-06 0.0176402" quat="0.9998 0.000578854 0.0200071 0.00015863" mass="0.009" diaginertia="2.52201e-07 2.36436e-07 9.27798e-08"/>
      <joint name="right_index_proximal_joint" pos="0 0 0" axis="0 1 0" range="0 1.41" actuatorfrcrange="-2 2"/>
      <geom type="mesh" rgba="1 1 1 1" mesh="right_index_proximal_link"/>
      <body name="right_index_distal_link" pos="0 0 0.032">
        <inertial pos="0.0060876 -0.0025871 0.0119976" quat="0.430999 0.780625 0.435425 0.123569" mass="0.011" diaginertia="1.32888e-06 1.05902e-06 3.35342e-07"/>
        <joint name="right_index_distal_joint" pos="0 0 0" axis="0 1 0" range="0 1.63" actuatorfrcrange="-2 2"/>
        <geom type="mesh" rgba="1 1 1 1" mesh="right_index_distal_link"/>
        <geom pos="0.014497 0 0.023303" quat="0.6361 0.734769 0.154182 -0.178098" type="mesh" rgba="1 1 1 1" mesh="right_index_touch_link"/>
      </body>
    </body>
    <body name="right_middle_proximal_link" pos="-0.0045767 0.010051 0.084993" quat="0.996681 -0.0175235 0.0746069 -0.0274369">
      <inertial pos="-0.00222511 5.25632e-06 0.0203008" quat="0.999816 0.00054813 0.0191911 0.000563992" mass="0.009" diaginertia="3.67373e-07 3.52646e-07 1.11857e-07"/>
      <joint name="right_middle_proximal_joint" pos="0 0 0" axis="0 1 0" range="0 1.41" actuatorfrcrange="-2 2"/>
      <geom type="mesh" rgba="1 1 1 1" mesh="right_middle_proximal_link"/>
      <body name="right_middle_distal_link" pos="0 0 0.037">
        <inertial pos="0.00383673 -2.75379e-08 0.0195634" quat="0.705722 0.0448414 0.0448463 0.705645" mass="0.011" diaginertia="1.02484e-06 1.00281e-06 1.14537e-07"/>
        <joint name="right_middle_distal_joint" pos="0 0 0" axis="0 1 0" range="0 1.63" actuatorfrcrange="-2 2"/>
        <geom type="mesh" rgba="1 1 1 1" mesh="right_middle_distal_link"/>
        <geom pos="0.0159759 0 0.0265894" quat="0.971858 0 0.235566 0" type="mesh" rgba="1 1 1 1" mesh="right_middle_touch_link"/>
      </body>
    </body>
    <body name="right_ring_proximal_link" pos="-0.0046709 -0.010037 0.083982" quat="0.996722 0.0175386 0.0740633 0.0274276">
      <inertial pos="-0.00234495 5.87955e-06 0.0191774" quat="0.999831 0.000632097 0.0183324 0.000717657" mass="0.009" diaginertia="3.14463e-07 2.97613e-07 1.01829e-07"/>
      <joint name="right_ring_proximal_joint" pos="0 0 0" axis="0 1 0" range="0 1.41" actuatorfrcrange="-2 2"/>
      <geom type="mesh" rgba="1 1 1 1" mesh="right_ring_proximal_link"/>
      <body name="right_ring_distal_link" pos="0 0 0.035">
        <inertial pos="0.0036609 5.57858e-08 0.0190714" quat="0.705755 0.0436974 0.0436974 0.705755" mass="0.011" diaginertia="9.70588e-07 9.499e-07 1.07356e-07"/>
        <joint name="right_ring_distal_joint" pos="0 0 0" axis="0 1 0" range="0 1.63" actuatorfrcrange="-2 2"/>
        <geom type="mesh" rgba="1 1 1 1" mesh="right_ring_distal_link"/>
        <geom pos="0.0154392 0 0.0260561" quat="0.971858 0 0.235566 0" type="mesh" rgba="1 1 1 1" mesh="right_ring_touch_link"/>
      </body>
    </body>
    <body name="right_pinky_proximal_link" pos="-0.0023566 -0.029366 0.078694" quat="0.992245 0.052387 0.0771065 0.0822136">
      <inertial pos="-0.00213212 7.75039e-06 0.0160672" quat="0.999803 0.000555178 0.0198191 0.000562874" mass="0.009" diaginertia="1.97745e-07 1.82023e-07 8.19805e-08"/>
      <joint name="right_pinky_proximal_joint" pos="0 0 0" axis="0 1 0" range="0 1.41" actuatorfrcrange="-2 2"/>
      <geom type="mesh" rgba="1 1 1 1" mesh="right_pinky_proximal_link"/>
      <body name="right_pinky_distal_link" pos="0 0 0.029">
        <inertial pos="0.00314681 -1.62934e-07 0.0154194" quat="0.705039 0.0540499 0.0540411 0.705038" mass="0.011" diaginertia="5.74716e-07 5.72915e-07 7.05144e-08"/>
        <joint name="right_pinky_distal_joint" pos="0 0 0" axis="0 1 0" range="0 1.63" actuatorfrcrange="-2 2"/>
        <geom type="mesh" rgba="1 1 1 1" mesh="right_pinky_distal_link"/>
        <geom pos="0.01401 0 0.021124" quat="0.971859 0 0.235565 0" type="mesh" rgba="1 1 1 1" mesh="right_pinky_touch_link"/>
      </body>
    </body>
  </worldbody>
</mujoco>