<!-- GENERATED by build_revo2.py - do not edit by hand.
     G1 body from r_robot.xml + BrainCo Revo2 hands on the wrists.
     Wrist mount transform is an estimate; tune LEFT/RIGHT_MOUNT_* there. -->
<mujoco model="g1_29dof_rev_1_0_with_revo2_hand">
  <compiler angle="radian" meshdir="meshes/" />
  <default>
    <joint armature="0.02" damping="0.4" frictionloss="0.005" />
  </default>
  <asset>
    <mesh name="pelvis" content_type="model/stl" file="pelvis.STL" />
    <mesh name="pelvis_contour_link" content_type="model/stl" file="pelvis_contour_link.STL" />
    <mesh name="left_hip_pitch_link" content_type="model/stl" file="left_hip_pitch_link.STL" />
    <mesh name="left_hip_roll_link" content_type="model/stl" file="left_hip_roll_link.STL" />
    <mesh name="left_hip_yaw_link" content_type="model/stl" file="left_hip_yaw_link.STL" />
    <mesh name="left_knee_link" content_type="model/stl" file="left_knee_link.STL" />
    <mesh name="left_ankle_pitch_link" content_type="model/stl" file="left_ankle_pitch_link.STL" />
    <mesh name="left_ankle_roll_link" content_type="model/stl" file="left_ankle_roll_link.STL" />
    <mesh name="right_hip_pitch_link" content_type="model/stl" file="right_hip_pitch_link.STL" />
    <mesh name="right_hip_roll_link" content_type="model/stl" file="right_hip_roll_link.STL" />
    <mesh name="right_hip_yaw_link" content_type="model/stl" file="right_hip_yaw_link.STL" />
    <mesh name="right_knee_link" content_type="model/stl" file="right_knee_link.STL" />
    <mesh name="right_ankle_pitch_link" content_type="model/stl" file="right_ankle_pitch_link.STL" />
    <mesh name="right_ankle_roll_link" content_type="model/stl" file="right_ankle_roll_link.STL" />
    <mesh name="waist_yaw_link_rev_1_0" content_type="model/stl" file="waist_yaw_link_rev_1_0.STL" />
    <mesh name="waist_roll_link_rev_1_0" content_type="model/stl" file="waist_roll_link_rev_1_0.STL" />
    <mesh name="torso_link_rev_1_0" content_type="model/stl" file="torso_link_rev_1_0.STL" />
    <mesh name="logo_link" content_type="model/stl" file="logo_link.STL" />
    <mesh name="head_link" content_type="model/stl" file="head_link.STL" />
    <mesh name="left_shoulder_pitch_link" content_type="model/stl" file="left_shoulder_pitch_link.STL" />
    <mesh name="left_shoulder_roll_link" content_type="model/stl" file="left_shoulder_roll_link.STL" />
    <mesh name="left_shoulder_yaw_link" content_type="model/stl" file="left_shoulder_yaw_link.STL" />
    <mesh name="left_elbow_link" content_type="model/stl" file="left_elbow_link.STL" />
    <mesh name="left_wrist_roll_link" content_type="model/stl" file="left_wrist_roll_link.STL" />
    <mesh name="left_wrist_pitch_link" content_type="model/stl" file="left_wrist_pitch_link.STL" />
    <mesh name="left_wrist_yaw_link" content_type="model/stl" file="left_wrist_yaw_link.STL" />
    <mesh name="right_shoulder_pitch_link" content_type="model/stl" file="right_shoulder_pitch_link.STL" />
    <mesh name="right_shoulder_roll_link" content_type="model/stl" file="right_shoulder_roll_link.STL" />
    <mesh name="right_shoulder_yaw_link" content_type="model/stl" file="right_shoulder_yaw_link.STL" />
    <mesh name="right_elbow_link" content_type="model/stl" file="right_elbow_link.STL" />
    <mesh name="right_wrist_roll_link" content_type="model/stl" file="right_wrist_roll_link.STL" />
    <mesh name="right_wrist_pitch_link" content_type="model/stl" file="right_wrist_pitch_link.STL" />
    <mesh name="right_wrist_yaw_link" content_type="model/stl" file="right_wrist_yaw_link.STL" />
    <mesh name="left_base_link" content_type="model/stl" file="revo2_left_hand/left_base_link.STL" />
    <mesh name="left_thumb_metacarpal_link" content_type="model/stl" file="revo2_left_hand/left_thumb_metacarpal_link.STL" />
    <mesh name="left_thumb_proximal_link" content_type="model/stl" file="revo2_left_hand/left_thumb_proximal_link.STL" />
    <mesh name="left_thumb_distal_link" content_type="model/stl" file="revo2_left_hand/left_thumb_distal_link.STL" />
    <mesh name="left_thumb_touch_link" content_type="model/stl" file="revo2_left_hand/left_thumb_touch_link.STL" />
    <mesh name="left_index_proximal_link" content_type="model/stl" file="revo2_left_hand/left_index_proximal_link.STL" />
    <mesh name="left_index_distal_link" content_type="model/stl" file="revo2_left_hand/left_index_distal_link.STL" />
    <mesh name="left_index_touch_link" content_type="model/stl" file="revo2_left_hand/left_index_touch_link.STL" />
    <mesh name="left_middle_proximal_link" content_type="model/stl" file="revo2_left_hand/left_middle_proximal_link.STL" />
    <mesh name="left_middle_distal_link" content_type="model/stl" file="revo2_left_hand/left_middle_distal_link.STL" />
    <mesh name="left_middle_touch_link" content_type="model/stl" file="revo2_left_hand/left_middle_touch_link.STL" />
    <mesh name="left_ring_proximal_link" content_type="model/stl" file="revo2_left_hand/left_ring_proximal_link.STL" />
    <mesh name="left_ring_distal_link" content_type="model/stl" file="revo2_left_hand/left_ring_distal_link.STL" />
    <mesh name="left_ring_touch_link" content_type="model/stl" file="revo2_left_hand/left_ring_touch_link.STL" />
    <mesh name="left_pinky_proximal_link" content_type="model/stl" file="revo2_left_hand/left_pinky_proximal_link.STL" />
    <mesh name="left_pinky_distal_link" content_type="model/stl" file="revo2_left_hand/left_pinky_distal_link.STL" />
    <mesh name="left_pinky_touch_link" content_type="model/stl" file="revo2_left_hand/left_pinky_touch_link.STL" />
    <mesh name="right_base_link" content_type="model/stl" file="revo2_right_hand/right_base_link.STL" />
    <mesh name="right_thumb_metacarpal_link" content_type="model/stl" file="revo2_right_hand/right_thumb_metacarpal_link.STL" />
    <mesh name="right_thumb_proximal_link" content_type="model/stl" file="revo2_right_hand/right_thumb_proximal_link.STL" />
    <mesh name="right_thumb_distal_link" content_type="model/stl" file="revo2_right_hand/right_thumb_distal_link.STL" />
    <mesh name="right_thumb_touch_link" content_type="model/stl" file="revo2_right_hand/right_thumb_touch_link.STL" />
    <mesh name="right_index_proximal_link" content_type="model/stl" file="revo2_right_hand/right_index_proximal_link.STL" />
    <mesh name="right_index_distal_link" content_type="model/stl" file="revo2_right_hand/right_index_distal_link.STL" />
    <mesh name="right_index_touch_link" content_type="model/stl" file="revo2_right_hand/right_index_touch_link.STL" />
    <mesh name="right_middle_proximal_link" content_type="model/stl" file="revo2_right_hand/right_middle_proximal_link.STL" />
    <mesh name="right_middle_distal_link" content_type="model/stl" file="revo2_right_hand/right_middle_distal_link.STL" />
    <mesh name="right_middle_touch_link" content_type="model/stl" file="revo2_right_hand/right_middle_touch_link.STL" />
    <mesh name="right_ring_proximal_link" content_type="model/stl" file="revo2_right_hand/right_ring_proximal_link.STL" />
    <mesh name="right_ring_distal_link" content_type="model/stl" file="revo2_right_hand/right_ring_distal_link.STL" />
    <mesh name="right_ring_touch_link" content_type="model/stl" file="revo2_right_hand/right_ring_touch_link.STL" />
    <mesh name="right_pinky_proximal_link" content_type="model/stl" file="revo2_right_hand/right_pinky_proximal_link.STL" />
    <mesh name="right_pinky_distal_link" content_type="model/stl" file="revo2_right_hand/right_pinky_distal_link.STL" />
    <mesh name="right_pinky_touch_link" content_type="model/stl" file="revo2_right_hand/right_pinky_touch_link.STL" />
  </asset>
  <worldbody>
    <body name="pelvis" pos="4.75 2.2 0.84" quat="0.747602 0 0 0.664147">
      <site name="imu" size="0.01" pos="-0.03959 -0.00224 0.13792" />
      <inertial pos="0 0 -0.07605" quat="1 0 -0.000399148 0" mass="3.813" diaginertia="0.010549 0.0093089 0.0079184" />
      <joint name="floating_base_joint" type="free" limited="false" actuatorfrclimited="false" />
      <geom type="mesh" contype="0" conaffinity="0" group="1" density="0" rgba="0.2 0.2 0.2 1" mesh="pelvis" />
      <geom type="mesh" contype="0" conaffinity="0" group="1" density="0" rgba="0.7 0.7 0.7 1" mesh="pelvis_contour_link" />
      <geom type="mesh" rgba="0.7 0.7 0.7 1" mesh="pelvis_contour_link" />
      <body name="left_hip_pitch_link" pos="0 0.064452 -0.1027">
        <inertial pos="0.002741 0.047791 -0.02606" quat="0.954862 0.293964 0.0302556 0.030122" mass="1.35" diaginertia="0.00181517 0.00153422 0.00116212" />
        <joint name="left_hip_pitch_joint" pos="0 0 0" axis="0 1 0" range="-2.5307 2.8798" actuatorfrcrange="-88 88" />
        <geom type="mesh" contype="0" conaffinity="0" group="1" density="0" rgba="0.2 0.2 0.2 1" mesh="left_hip_pitch_link" />
        <geom type="mesh" rgba="0.2 0.2 0.2 1" mesh="left_hip_pitch_link" />
        <body name="left_hip_roll_link" pos="0 0.052 -0.030465" quat="0.996179 0 -0.0873386 0">
          <inertial pos="0.029812 -0.001045 -0.087934" quat="0.977808 -1.97119e-05 0.205576 -0.0403793" mass="1.52" diaginertia="0.00254986 0.00241169 0.00148755" />
          <joint name="left_hip_roll_joint" pos="0 0 0" axis="1 0 0" range="-0.5236 2.9671" actuatorfrcrange="-139 139" />
          <geom type="mesh" contype="0" conaffinity="0" group="1" density="0" rgba="0.7 0.7 0.7 1" mesh="left_hip_roll_link" />
          <geom type="mesh" rgba="0.7 0.7 0.7 1" mesh="left_hip_roll_link" />
          <body name="left_hip_yaw_link" pos="0.025001 0 -0.12412">
            <inertial pos="-0.057709 -0.010981 -0.15078" quat="0.600598 0.15832 0.223482 0.751181" mass="1.702" diaginertia="0.00776166 0.00717575 0.00160139" />
            <joint name="left_hip_yaw_joint" pos="0 0 0" axis="0 0 1" range="-2.7576 2.7576" actuatorfrcrange="-88 88" />
            <geom type="mesh" contype="0" conaffinity="0" group="1" density="0" rgba="0.7 0.7 0.7 1" mesh="left_hip_yaw_link" />
            <geom type="mesh" rgba="0.7 0.7 0.7 1" mesh="left_hip_yaw_link" />
            <body name="left_knee_link" pos="-0.078273 0.0021489 -0.17734" quat="0.996179 0 0.0873386 0">
              <inertial pos="0.005457 0.003964 -0.12074" quat="0.923418 -0.0327699 0.0158246 0.382067" mass="1.932" diaginertia="0.0113804 0.0112778 0.00146458" />
              <joint name="left_knee_joint" pos="0 0 0" axis="0 1 0" range="-0.087267 2.8798" actuatorfrcrange="-139 139" />
              <geom type="mesh" contype="0" conaffinity="0" group="1" density="0" rgba="0.7 0.7 0.7 1" mesh="left_knee_link" />
              <geom type="mesh" rgba="0.7 0.7 0.7 1" mesh="left_knee_link" />
              <body name="left_ankle_pitch_link" pos="0 -9.4445e-05 -0.30001">
                <inertial pos="-0.007269 0 0.011137" quat="0.603053 0.369225 0.369225 0.603053" mass="0.074" diaginertia="1.89e-05 1.40805e-05 6.9195e-06" />
                <joint name="left_ankle_pitch_joint" pos="0 0 0" axis="0 1 0" range="-0.87267 0.5236" actuatorfrcrange="-35 35" />
                <geom type="mesh" contype="0" conaffinity="0" group="1" density="0" rgba="0.7 0.7 0.7 1" mesh="left_ankle_pitch_link" />
                <geom type="mesh" rgba="0.7 0.7 0.7 1" mesh="left_ankle_pitch_link" />
                <body name="left_ankle_roll_link" pos="0 0 -0.017558">
                  <inertial pos="0.026505 0 -0.016425" quat="-0.000481092 0.728482 -0.000618967 0.685065" mass="0.608" diaginertia="0.00167218 0.0016161 0.000217621" />
                  <joint name="left_ankle_roll_joint" pos="0 0 0" axis="1 0 0" range="-0.2618 0.2618" actuatorfrcrange="-35 35" />
                  <geom type="mesh" contype="0" conaffinity="0" group="1" density="0" rgba="0.2 0.2 0.2 1" mesh="left_ankle_roll_link" />
                  <geom size="0.005" pos="-0.05 0.025 -0.03" rgba="0.2 0.2 0.2 1" />
                  <geom size="0.005" pos="-0.05 -0.025 -0.03" rgba="0.2 0.2 0.2 1" />
                  <geom size="0.005" pos="0.12 0.03 -0.03" rgba="0.2 0.2 0.2 1" />
                  <geom size="0.005" pos="0.12 -0.03 -0.03" rgba="0.2 0.2 0.2 1" />
                </body>
              </body>
            </body>
          </body>
        </body>
      </body>
      <body name="right_hip_pitch_link" pos="0 -0.064452 -0.1027">
        <inertial pos="0.002741 -0.047791 -0.02606" quat="0.954862 -0.293964 0.0302556 -0.030122" mass="1.35" diaginertia="0.00181517 0.00153422 0.00116212" />
        <joint name="right_hip_pitch_joint" pos="0 0 0" axis="0 1 0" range="-2.5307 2.8798" actuatorfrcrange="-88 88" />
        <geom type="mesh" contype="0" conaffinity="0" group="1" density="0" rgba="0.2 0.2 0.2 1" mesh="right_hip_pitch_link" />
        <geom type="mesh" rgba="0.2 0.2 0.2 1" mesh="right_hip_pitch_link" />
        <body name="right_hip_roll_link" pos="0 -0.052 -0.030465" quat="0.996179 0 -0.0873386 0">
          <inertial pos="0.029812 0.001045 -0.087934" quat="0.977808 1.97119e-05 0.205576 0.0403793" mass="1.52" diaginertia="0.00254986 0.00241169 0.00148755" />
          <joint name="right_hip_roll_joint" pos="0 0 0" axis="1 0 0" range="-2.9671 0.5236" actuatorfrcrange="-139 139" />
          <geom type="mesh" contype="0" conaffinity="0" group="1" density="0" rgba="0.7 0.7 0.7 1" mesh="right_hip_roll_link" />
          <geom type="mesh" rgba="0.7 0.7 0.7 1" mesh="right_hip_roll_link" />
          <body name="right_hip_yaw_link" pos="0.025001 0 -0.12412">
            <inertial pos="-0.057709 0.010981 -0.15078" quat="0.751181 0.223482 0.15832 0.600598" mass="1.702" diaginertia="0.00776166 0.00717575 0.00160139" />
            <joint name="right_hip_yaw_joint" pos="0 0 0" axis="0 0 1" range="-2.7576 2.7576" actuatorfrcrange="-88 88" />
            <geom type="mesh" contype="0" conaffinity="0" group="1" density="0" rgba="0.7 0.7 0.7 1" mesh="right_hip_yaw_link" />
            <geom type="mesh" rgba="0.7 0.7 0.7 1" mesh="right_hip_yaw_link" />
            <body name="right_knee_link" pos="-0.078273 -0.0021489 -0.17734" quat="0.996179 0 0.0873386 0">
              <inertial pos="0.005457 -0.003964 -0.12074" quat="0.923439 0.0345276 0.0116333 -0.382012" mass="1.932" diaginertia="0.011374 0.0112843 0.00146452" />
              <joint name="right_knee_joint" pos="0 0 0" axis="0 1 0" range="-0.087267 2.8798" actuatorfrcrange="-139 139" />
              <geom type="mesh" contype="0" conaffinity="0" group="1" density="0" rgba="0.7 0.7 0.7 1" mesh="right_knee_link" />
              <geom type="mesh" rgba="0.7 0.7 0.7 1" mesh="right_knee_link" />
              <body name="right_ankle_pitch_link" pos="0 9.4445e-05 -0.30001">
                <inertial pos="-0.007269 0 0.011137" quat="0.603053 0.369225 0.369225 0.603053" mass="0.074" diaginertia="1.89e-05 1.40805e-05 6.9195e-06" />
                <joint name="right_ankle_pitch_joint" pos="0 0 0" axis="0 1 0" range="-0.87267 0.5236" actuatorfrcrange="-35 35" />
                <geom type="mesh" contype="0" conaffinity="0" group="1" density="0" rgba="0.7 0.7 0.7 1" mesh="right_ankle_pitch_link" />
                <geom type="mesh" rgba="0.7 0.7 0.7 1" mesh="right_ankle_pitch_link" />
                <body name="right_ankle_roll_link" pos="0 0 -0.017558">
                  <inertial pos="0.026505 0 -0.016425" quat="0.000481092 0.728482 0.000618967 0.685065" mass="0.608" diaginertia="0.00167218 0.0016161 0.000217621" />
                  <joint name="right_ankle_roll_joint" pos="0 0 0" axis="1 0 0" range="-0.2618 0.2618" actuatorfrcrange="-35 35" />
                  <geom type="mesh" contype="0" conaffinity="0" group="1" density="0" rgba="0.2 0.2 0.2 1" mesh="right_ankle_roll_link" />
                  <geom size="0.005" pos="-0.05 0.025 -0.03" rgba="0.2 0.2 0.2 1" />
                  <geom size="0.005" pos="-0.05 -0.025 -0.03" rgba="0.2 0.2 0.2 1" />
                  <geom size="0.005" pos="0.12 0.03 -0.03" rgba="0.2 0.2 0.2 1" />
                  <geom size="0.005" pos="0.12 -0.03 -0.03" rgba="0.2 0.2 0.2 1" />
                </body>
              </body>
            </body>
          </body>
        </body>
      </body>
      <body name="waist_yaw_link">
        <inertial pos="0.003494 0.000233 0.018034" quat="0.289697 0.591001 -0.337795 0.672821" mass="0.214" diaginertia="0.000163531 0.000107714 0.000102205" />
        <joint name="waist_yaw_joint" pos="0 0 0" axis="0 0 1" range="-2.618 2.618" actuatorfrcrange="-88 88" />
        <geom type="mesh" contype="0" conaffinity="0" group="1" density="0" rgba="0.7 0.7 0.7 1" mesh="waist_yaw_link_rev_1_0" />
        <body name="waist_roll_link" pos="-0.0039635 0 0.044">
          <inertial pos="0 2.3e-05 0" quat="0.5 0.5 -0.5 0.5" mass="0.086" diaginertia="8.245e-06 7.079e-06 6.339e-06" />
          <joint name="waist_roll_joint" pos="0 0 0" axis="1 0 0" range="-0.52 0.52" actuatorfrcrange="-35 35" />
          <geom type="mesh" contype="0" conaffinity="0" group="1" density="0" rgba="0.7 0.7 0.7 1" mesh="waist_roll_link_rev_1_0" />
          <body name="torso_link">
            <inertial pos="0.0013154 0.000855537 0.184599" quat="0.999895 -0.00548212 0.0132901 0.00194196" mass="7.817" diaginertia="0.121734 0.109736 0.0274043" />
            <joint name="waist_pitch_joint" pos="0 0 0" axis="0 1 0" range="-0.52 0.52" actuatorfrcrange="-35 35" />
            <geom type="mesh" contype="0" conaffinity="0" group="1" density="0" rgba="0.7 0.7 0.7 1" mesh="torso_link_rev_1_0" />
            <geom type="mesh" rgba="0.7 0.7 0.7 1" mesh="torso_link_rev_1_0" />
            <geom pos="0.0039635 0 -0.044" quat="1 0 0 0" type="mesh" contype="0" conaffinity="0" group="1" density="0" rgba="0.2 0.2 0.2 1" mesh="logo_link" />
            <geom pos="0.0039635 0 -0.044" quat="1 0 0 0" type="mesh" rgba="0.2 0.2 0.2 1" mesh="logo_link" />
            <geom pos="0.0039635 0 -0.044" type="mesh" contype="0" conaffinity="0" group="1" density="0" rgba="0.2 0.2 0.2 1" mesh="head_link" />
            <geom pos="0.0039635 0 -0.044" type="mesh" rgba="0.2 0.2 0.2 1" mesh="head_link" />
            <camera name="ego_view" pos="0.07 0 0.36" euler="0 -0.80 -1.57" fovy="100" />
            <body name="left_shoulder_pitch_link" pos="0.0039563 0.10022 0.24778" quat="0.990264 0.139201 1.38722e-05 -9.86868e-05">
              <inertial pos="0 0.035892 -0.011628" quat="0.654152 0.0130458 -0.326267 0.68225" mass="0.718" diaginertia="0.000465864 0.000432842 0.000406394" />
              <joint name="left_shoulder_pitch_joint" pos="0 0 0" axis="0 1 0" range="-3.0892 2.6704" actuatorfrcrange="-25 25" />
              <geom type="mesh" contype="0" conaffinity="0" group="1" density="0" rgba="0.7 0.7 0.7 1" mesh="left_shoulder_pitch_link" />
              <geom size="0.03 0.025" pos="0 0.04 -0.01" quat="0.707107 0 0.707107 0" type="cylinder" rgba="0.7 0.7 0.7 1" />
              <body name="left_shoulder_roll_link" pos="0 0.038 -0.013831" quat="0.990268 -0.139172 0 0">
                <inertial pos="-0.000227 0.00727 -0.063243" quat="0.701256 -0.0196223 -0.00710317 0.712604" mass="0.643" diaginertia="0.000691311 0.000618011 0.000388977" />
                <joint name="left_shoulder_roll_joint" pos="0 0 0" axis="1 0 0" range="-1.5882 2.2515" actuatorfrcrange="-25 25" />
                <geom type="mesh" contype="0" conaffinity="0" group="1" density="0" rgba="0.7 0.7 0.7 1" mesh="left_shoulder_roll_link" />
                <geom size="0.03 0.015" pos="-0.004 0.006 -0.053" type="cylinder" rgba="0.7 0.7 0.7 1" />
                <body name="left_shoulder_yaw_link" pos="0 0.00624 -0.1032">
                  <inertial pos="0.010773 -0.002949 -0.072009" quat="0.716879 -0.0964829 -0.0679942 0.687134" mass="0.734" diaginertia="0.00106187 0.00103217 0.000400661" />
                  <joint name="left_shoulder_yaw_joint" pos="0 0 0" axis="0 0 1" range="-2.618 2.618" actuatorfrcrange="-25 25" />
                  <geom type="mesh" contype="0" conaffinity="0" group="1" density="0" rgba="0.7 0.7 0.7 1" mesh="left_shoulder_yaw_link" />
                  <geom type="mesh" rgba="0.7 0.7 0.7 1" mesh="left_shoulder_yaw_link" />
                  <body name="left_elbow_link" pos="0.015783 0 -0.080518">
                    <inertial pos="0.064956 0.004454 -0.010062" quat="0.541765 0.636132 0.388821 0.388129" mass="0.6" diaginertia="0.000443035 0.000421612 0.000259353" />
                    <joint name="left_elbow_joint" pos="0 0 0" axis="0 1 0" range="-1.0472 2.0944" actuatorfrcrange="-25 25" />
                    <geom type="mesh" contype="0" conaffinity="0" group="1" density="0" rgba="0.7 0.7 0.7 1" mesh="left_elbow_link" />
                    <geom type="mesh" rgba="0.7 0.7 0.7 1" mesh="left_elbow_link" />
                    <body name="left_wrist_roll_link" pos="0.1 0.00188791 -0.01">
                      <inertial pos="0.0171394 0.000537591 4.8864e-07" quat="0.575338 0.411667 -0.574906 0.411094" mass="0.085445" diaginertia="5.48211e-05 4.96646e-05 3.57798e-05" />
                      <joint name="left_wrist_roll_joint" pos="0 0 0" axis="1 0 0" range="-1.97222 1.97222" actuatorfrcrange="-25 25" />
                      <geom type="mesh" contype="0" conaffinity="0" group="1" density="0" rgba="0.7 0.7 0.7 1" mesh="left_wrist_roll_link" />
                      <geom type="mesh" rgba="0.7 0.7 0.7 1" mesh="left_wrist_roll_link" />
                      <body name="left_wrist_pitch_link" pos="0.038 0 0">
                        <inertial pos="0.0229999 -0.00111685 -0.00111658" quat="0.249998 0.661363 0.293036 0.643608" mass="0.48405" diaginertia="0.000430353 0.000429873 0.000164648" />
                        <joint name="left_wrist_pitch_joint" pos="0 0 0" axis="0 1 0" range="-1.61443 1.61443" actuatorfrcrange="-5 5" />
                        <geom type="mesh" contype="0" conaffinity="0" group="1" density="0" rgba="0.7 0.7 0.7 1" mesh="left_wrist_pitch_link" />
                        <geom type="mesh" rgba="0.7 0.7 0.7 1" mesh="left_wrist_pitch_link" />
                        <body name="left_wrist_yaw_link" pos="0.046 0 0">
                          <camera name="ego_view_left_mono" pos="0.20 0.0 0.12" euler="0 0.5 0" fovy="80" mode="fixed" />
                          <inertial pos="0.0325531 -0.0397494 -0.00195093" quat="0.677571 0.725684 0.0635699 0.101189" mass="0.226006" diaginertia="0.000406774 0.000351019 0.000144526" />
                          <joint name="left_wrist_yaw_joint" pos="0 0 0" axis="0 0 1" range="-1.61443 1.61443" actuatorfrcrange="-5 5" />
                          <geom type="mesh" contype="0" conaffinity="0" group="1" density="0" rgba="0.7 0.7 0.7 1" mesh="left_wrist_yaw_link" />
                          <geom type="mesh" rgba="0.7 0.7 0.7 1" mesh="left_wrist_yaw_link" />
                          <body name="left_hand_mount" pos="0.0415 0 0" quat="0.483354 -0.516109 0.483354 -0.516109">
                            <geom type="mesh" rgba="1 1 1 1" mesh="left_base_link" />
                            <body name="left_thumb_metacarpal_link" pos="0.0045 -0.019 0.027825" quat="0.99648 0 0 0.0838365">
                              <inertial pos="1.52304e-05 -0.0070724 -0.0042084" quat="0.882814 0.0586739 -0.0302438 0.465061" mass="0.01" diaginertia="1.66114e-07 1.56005e-07 4.93864e-08" />
                              <joint name="left_thumb_metacarpal_joint" pos="0 0 0" axis="0 0 1" range="0 1.57" actuatorfrcrange="-0.5 0.5" />
                              <geom type="mesh" rgba="1 1 1 1" mesh="left_thumb_metacarpal_link" />
                              <body name="left_thumb_proximal_link" pos="0 -0.014227 0" quat="0.986557 -0.0765206 0.124804 -0.0726253">
                                <inertial pos="-3.69149e-07 -0.0277016 -0.00202668" quat="0.503512 0.49651 -0.496419 0.50351" mass="0.05" diaginertia="2.56296e-06 2.40451e-06 5.11892e-07" />
                                <joint name="left_thumb_proximal_joint" pos="0 0 0" axis="-1 0 0" range="0 1.03" actuatorfrcrange="-1.1 1.1" />
                                <geom type="mesh" rgba="1 1 1 1" mesh="left_thumb_proximal_link" />
                                <body name="left_thumb_distal_link" pos="0 -0.052 0">
                                  <inertial pos="0.00230662 -0.0109516 -0.00123487" quat="-0.140354 0.818621 0.12206 0.54338" mass="0.012" diaginertia="8.71595e-07 6.87762e-07 3.48324e-07" />
                                  <joint name="left_thumb_distal_joint" pos="0 0 0" axis="-1 0 0" range="0 1.03" actuatorfrcrange="-1.1 1.1" />
                                  <geom type="mesh" rgba="1 1 1 1" mesh="left_thumb_distal_link" />
                                  <geom pos="0 -0.013836 0.0076686" quat="0.99618 0.0873286 0 0" type="mesh" rgba="1 1 1 1" mesh="left_thumb_touch_link" />
                                </body>
                              </body>
                            </body>
                            <body name="left_index_proximal_link" pos="-0.0021349 -0.029578 0.080876" quat="0.992147 0.0522807 0.0783652 0.0822789">
                              <inertial pos="-0.00223539 -3.80545e-06 0.0176439" quat="0.999799 -0.000616966 0.0200059 -0.000754874" mass="0.009" diaginertia="2.52119e-07 2.36343e-07 9.27846e-08" />
                              <joint name="left_index_proximal_joint" pos="0 0 0" axis="0 1 0" range="0 1.41" actuatorfrcrange="-2 2" />
                              <geom type="mesh" rgba="1 1 1 1" mesh="left_index_proximal_link" />
                              <body name="left_index_distal_link" pos="0 0 0.032">
                                <inertial pos="0.00317525 5.29762e-08 0.0169679" quat="0.706026 0.0390791 0.0390754 0.706026" mass="0.011" diaginertia="7.45606e-07 7.32245e-07 8.66723e-08" />
                                <joint name="left_index_distal_joint" pos="0 0 0" axis="0 1 0" range="0 1.63" actuatorfrcrange="-2 2" />
                                <geom type="mesh" rgba="1 1 1 1" mesh="left_index_distal_link" />
                                <geom pos="0.014497 0 0.023303" quat="0.971859 0 0.235565 0" type="mesh" rgba="1 1 1 1" mesh="left_index_touch_link" />
                              </body>
                            </body>
                            <body name="left_middle_proximal_link" pos="-0.0045935 -0.010061 0.084993" quat="0.996681 0.0175235 0.0746069 0.0274369">
                              <inertial pos="-0.00222419 -3.61991e-06 0.020305" quat="0.999816 -0.000555887 0.019164 -0.000888931" mass="0.009" diaginertia="3.6726e-07 3.52522e-07 1.11867e-07" />
                              <joint name="left_middle_proximal_joint" pos="0 0 0" axis="0 1 0" range="0 1.41" actuatorfrcrange="-2 2" />
                              <geom type="mesh" rgba="1 1 1 1" mesh="left_middle_proximal_link" />
                              <body name="left_middle_distal_link" pos="0 0 0.037" quat="0.997999 0 0.0632278 0">
                                <inertial pos="0.00140097 -2.38806e-08 0.0199686" quat="0.707155 0.00308064 0.00308112 0.707045" mass="0.011" diaginertia="1.04502e-06 1.02638e-06 1.11152e-07" />
                                <joint name="left_middle_distal_joint" pos="0 0 0" axis="0 1 0" range="0 1.63" actuatorfrcrange="-2 2" />
                                <geom type="mesh" rgba="1 1 1 1" mesh="left_middle_distal_link" />
                                <geom pos="0.012493 0 0.028393" quat="0.984807 0 0.17365 0" type="mesh" rgba="1 1 1 1" mesh="left_middle_touch_link" />
                              </body>
                            </body>
                            <body name="left_ring_proximal_link" pos="-0.0046877 0.010026 0.083982" quat="0.996722 -0.0175386 0.0740633 -0.0274276">
                              <inertial pos="-0.00234461 -5.32058e-06 0.0191786" quat="0.999832 -0.00064229 0.0183097 -0.000744974" mass="0.009" diaginertia="3.14467e-07 2.97624e-07 1.01836e-07" />
                              <joint name="left_ring_proximal_joint" pos="0 0 0" axis="0 1 0" range="0 1.41" actuatorfrcrange="-2 2" />
                              <geom type="mesh" rgba="1 1 1 1" mesh="left_ring_proximal_link" />
                              <body name="left_ring_distal_link" pos="0 0 0.035" quat="0.997999 0 0.0632278 0">
                                <inertial pos="0.00129034 4.53539e-08 0.0194548" quat="0.707082 0.00225217 0.00225203 0.707124" mass="0.011" diaginertia="9.89389e-07 9.72051e-07 1.04006e-07" />
                                <joint name="left_ring_distal_joint" pos="0 0 0" axis="0 1 0" range="0 1.63" actuatorfrcrange="-2 2" />
                                <geom type="mesh" rgba="1 1 1 1" mesh="left_ring_distal_link" />
                                <geom pos="0.012028 0 0.027796" quat="0.984807 0 0.17365 0" type="mesh" rgba="1 1 1 1" mesh="left_ring_touch_link" />
                              </body>
                            </body>
                            <body name="left_pinky_proximal_link" pos="-0.0023733 0.029356 0.078694" quat="0.992245 -0.052387 0.0771065 -0.0822136">
                              <inertial pos="-0.00213267 -7.0226e-06 0.016068" quat="0.999803 -0.000517111 0.0198307 -0.000287779" mass="0.009" diaginertia="1.97736e-07 1.82023e-07 8.19937e-08" />
                              <joint name="left_pinky_proximal_joint" pos="0 0 0" axis="0 1 0" range="0 1.41" actuatorfrcrange="-2 2" />
                              <geom type="mesh" rgba="1 1 1 1" mesh="left_pinky_proximal_link" />
                              <body name="left_pinky_distal_link" pos="0 0 0.029">
                                <inertial pos="0.00314664 -1.39005e-07 0.0154188" quat="0.705039 0.0540449 0.0540391 0.705038" mass="0.011" diaginertia="5.74708e-07 5.72908e-07 7.05104e-08" />
                                <joint name="left_pinky_distal_joint" pos="0 0 0" axis="0 1 0" range="0 1.63" actuatorfrcrange="-2 2" />
                                <geom type="mesh" rgba="1 1 1 1" mesh="left_pinky_distal_link" />
                                <geom pos="0.01401 0 0.021124" quat="0.971859 0 0.235565 0" type="mesh" rgba="1 1 1 1" mesh="left_pinky_touch_link" />
                              </body>
                            </body>
                          </body>
                        </body>
                      </body>
                    </body>
                  </body>
                </body>
              </body>
            </body>
            <body name="right_shoulder_pitch_link" pos="0.0039563 -0.10021 0.24778" quat="0.990264 -0.139201 1.38722e-05 9.86868e-05">
              <inertial pos="0 -0.035892 -0.011628" quat="0.68225 -0.326267 0.0130458 0.654152" mass="0.718" diaginertia="0.000465864 0.000432842 0.000406394" />
              <joint name="right_shoulder_pitch_joint" pos="0 0 0" axis="0 1 0" range="-3.0892 2.6704" actuatorfrcrange="-25 25" />
              <geom type="mesh" contype="0" conaffinity="0" group="1" density="0" rgba="0.7 0.7 0.7 1" mesh="right_shoulder_pitch_link" />
              <geom size="0.03 0.025" pos="0 -0.04 -0.01" quat="0.707107 0 0.707107 0" type="cylinder" rgba="0.7 0.7 0.7 1" />
              <body name="right_shoulder_roll_link" pos="0 -0.038 -0.013831" quat="0.990268 0.139172 0 0">
                <inertial pos="-0.000227 -0.00727 -0.063243" quat="0.712604 -0.00710317 -0.0196223 0.701256" mass="0.643" diaginertia="0.000691311 0.000618011 0.000388977" />
                <joint name="right_shoulder_roll_joint" pos="0 0 0" axis="1 0 0" range="-2.2515 1.5882" actuatorfrcrange="-25 25" />
                <geom type="mesh" contype="0" conaffinity="0" group="1" density="0" rgba="0.7 0.7 0.7 1" mesh="right_shoulder_roll_link" />
                <geom size="0.03 0.015" pos="-0.004 -0.006 -0.053" type="cylinder" rgba="0.7 0.7 0.7 1" />
                <body name="right_shoulder_yaw_link" pos="0 -0.00624 -0.1032">
                  <inertial pos="0.010773 0.002949 -0.072009" quat="0.687134 -0.0679942 -0.0964829 0.716879" mass="0.734" diaginertia="0.00106187 0.00103217 0.000400661" />
                  <joint name="right_shoulder_yaw_joint" pos="0 0 0" axis="0 0 1" range="-2.618 2.618" actuatorfrcrange="-25 25" />
                  <geom type="mesh" contype="0" conaffinity="0" group="1" density="0" rgba="0.7 0.7 0.7 1" mesh="right_shoulder_yaw_link" />
                  <geom type="mesh" rgba="0.7 0.7 0.7 1" mesh="right_shoulder_yaw_link" />
                  <body name="right_elbow_link" pos="0.015783 0 -0.080518">
                    <inertial pos="0.064956 -0.004454 -0.010062" quat="0.388129 0.388821 0.636132 0.541765" mass="0.6" diaginertia="0.000443035 0.000421612 0.000259353" />
                    <joint name="right_elbow_joint" pos="0 0 0" axis="0 1 0" range="-1.0472 2.0944" actuatorfrcrange="-25 25" />
                    <geom type="mesh" contype="0" conaffinity="0" group="1" density="0" rgba="0.7 0.7 0.7 1" mesh="right_elbow_link" />
                    <geom type="mesh" rgba="0.7 0.7 0.7 1" mesh="right_elbow_link" />
                    <body name="right_wrist_roll_link" pos="0.1 -0.00188791 -0.01">
                      <inertial pos="0.0171394 -0.000537591 4.8864e-07" quat="0.411667 0.575338 -0.411094 0.574906" mass="0.085445" diaginertia="5.48211e-05 4.96646e-05 3.57798e-05" />
                      <joint name="right_wrist_roll_joint" pos="0 0 0" axis="1 0 0" range="-1.97222 1.97222" actuatorfrcrange="-25 25" />
                      <geom type="mesh" contype="0" conaffinity="0" group="1" density="0" rgba="0.7 0.7 0.7 1" mesh="right_wrist_roll_link" />
                      <geom type="mesh" rgba="0.7 0.7 0.7 1" mesh="right_wrist_roll_link" />
                      <body name="right_wrist_pitch_link" pos="0.038 0 0">
                        <inertial pos="0.0229999 0.00111685 -0.00111658" quat="0.643608 0.293036 0.661363 0.249998" mass="0.48405" diaginertia="0.000430353 0.000429873 0.000164648" />
                        <joint name="right_wrist_pitch_joint" pos="0 0 0" axis="0 1 0" range="-1.61443 1.61443" actuatorfrcrange="-5 5" />
                        <geom type="mesh" contype="0" conaffinity="0" group="1" density="0" rgba="0.7 0.7 0.7 1" mesh="right_wrist_pitch_link" />
                        <geom type="mesh" rgba="0.7 0.7 0.7 1" mesh="right_wrist_pitch_link" />
                        <body name="right_wrist_yaw_link" pos="0.046 0 0">
                          <camera name="ego_view_right_mono" pos="0.20 0.0 0.12" euler="0 0.5 0" fovy="80" mode="fixed" />
                          <inertial pos="0.0325685 -0.0401189 0.00236866" quat="0.708687 0.693377 0.050798 0.120044" mass="0.226006" diaginertia="0.000399854 0.000342942 0.000144291" />
                          <joint name="right_wrist_yaw_joint" pos="0 0 0" axis="0 0 1" range="-1.61443 1.61443" actuatorfrcrange="-5 5" />
                          <geom type="mesh" contype="0" conaffinity="0" group="1" density="0" rgba="0.7 0.7 0.7 1" mesh="right_wrist_yaw_link" />
                          <geom type="mesh" rgba="0.7 0.7 0.7 1" mesh="right_wrist_yaw_link" />
                          <body name="right_hand_mount" pos="0.0415 0 0" quat="0.483364 0.516100 0.483364 0.516100">
                            <geom type="mesh" rgba="1 1 1 1" mesh="right_base_link" />
                            <body name="right_thumb_metacarpal_link" pos="0.005619 0.019867 0.027825" quat="0.99648 0 0 -0.0838365">
                              <inertial pos="1.51106e-05 0.00707243 -0.00420847" quat="0.465075 -0.0302438 0.0586743 0.882807" mass="0.01" diaginertia="1.66115e-07 1.56006e-07 4.9387e-08" />
                              <joint name="right_thumb_metacarpal_joint" pos="0 0 0" axis="0 0 -1" range="0 1.57" actuatorfrcrange="-0.5 0.5" />
                              <geom type="mesh" rgba="1 1 1 1" mesh="right_thumb_metacarpal_link" />
                              <body name="right_thumb_proximal_link" pos="0 0.014227 0" quat="0.986557 0.0765206 0.124804 0.0726253">
                                <inertial pos="-4.6972e-07 0.0277015 -0.00202656" quat="0.496496 0.503512 -0.503514 0.496429" mass="0.05" diaginertia="2.56295e-06 2.40452e-06 5.11916e-07" />
                                <joint name="right_thumb_proximal_joint" pos="0 0 0" axis="1 0 0" range="0 1.03" actuatorfrcrange="-1.1 1.1" />
                                <geom type="mesh" rgba="1 1 1 1" mesh="right_thumb_proximal_link" />
                                <body name="right_thumb_distal_link" pos="0 0.052 0">
                                  <inertial pos="-0.00229861 0.00826353 -0.00122274" quat="0.508224 0.321185 -0.717381 0.352014" mass="0.012" diaginertia="1.56378e-06 1.44424e-06 2.76577e-07" />
                                  <joint name="right_thumb_distal_joint" pos="0 0 0" axis="1 0 0" range="0 1.03" actuatorfrcrange="-1.1 1.1" />
                                  <geom type="mesh" rgba="1 1 1 1" mesh="right_thumb_distal_link" />
                                  <geom pos="0 0.0137928 0.0076766" quat="0.999443 -0.033369 0 0" type="mesh" rgba="1 1 1 1" mesh="right_thumb_touch_link" />
                                </body>
                              </body>
                            </body>
                            <body name="right_index_proximal_link" pos="-0.0021181 0.029568 0.080876" quat="0.992147 -0.0522807 0.0783652 -0.0822789">
                              <inertial pos="-0.00223495 3.15875e-06 0.0176402" quat="0.9998 0.000578854 0.0200071 0.00015863" mass="0.009" diaginertia="2.52201e-07 2.36436e-07 9.27798e-08" />
                              <joint name="right_index_proximal_joint" pos="0 0 0" axis="0 1 0" range="0 1.41" actuatorfrcrange="-2 2" />
                              <geom type="mesh" rgba="1 1 1 1" mesh="right_index_proximal_link" />
                              <body name="right_index_distal_link" pos="0 0 0.032">
                                <inertial pos="0.0060876 -0.0025871 0.0119976" quat="0.430999 0.780625 0.435425 0.123569" mass="0.011" diaginertia="1.32888e-06 1.05902e-06 3.35342e-07" />
                                <joint name="right_index_distal_joint" pos="0 0 0" axis="0 1 0" range="0 1.63" actuatorfrcrange="-2 2" />
                                <geom type="mesh" rgba="1 1 1 1" mesh="right_index_distal_link" />
                                <geom pos="0.014497 0 0.023303" quat="0.6361 0.734769 0.154182 -0.178098" type="mesh" rgba="1 1 1 1" mesh="right_index_touch_link" />
                              </body>
                            </body>
                            <body name="right_middle_proximal_link" pos="-0.0045767 0.010051 0.084993" quat="0.996681 -0.0175235 0.0746069 -0.0274369">
                              <inertial pos="-0.00222511 5.25632e-06 0.0203008" quat="0.999816 0.00054813 0.0191911 0.000563992" mass="0.009" diaginertia="3.67373e-07 3.52646e-07 1.11857e-07" />
                              <joint name="right_middle_proximal_joint" pos="0 0 0" axis="0 1 0" range="0 1.41" actuatorfrcrange="-2 2" />
                              <geom type="mesh" rgba="1 1 1 1" mesh="right_middle_proximal_link" />
                              <body name="right_middle_distal_link" pos="0 0 0.037">
                                <inertial pos="0.00383673 -2.75379e-08 0.0195634" quat="0.705722 0.0448414 0.0448463 0.705645" mass="0.011" diaginertia="1.02484e-06 1.00281e-06 1.14537e-07" />
                                <joint name="right_middle_distal_joint" pos="0 0 0" axis="0 1 0" range="0 1.63" actuatorfrcrange="-2 2" />
                                <geom type="mesh" rgba="1 1 1 1" mesh="right_middle_distal_link" />
                                <geom pos="0.0159759 0 0.0265894" quat="0.971858 0 0.235566 0" type="mesh" rgba="1 1 1 1" mesh="right_middle_touch_link" />
                              </body>
                            </body>
                            <body name="right_ring_proximal_link" pos="-0.0046709 -0.010037 0.083982" quat="0.996722 0.0175386 0.0740633 0.0274276">
                              <inertial pos="-0.00234495 5.87955e-06 0.0191774" quat="0.999831 0.000632097 0.0183324 0.000717657" mass="0.009" diaginertia="3.14463e-07 2.97613e-07 1.01829e-07" />
                              <joint name="right_ring_proximal_joint" pos="0 0 0" axis="0 1 0" range="0 1.41" actuatorfrcrange="-2 2" />
                              <geom type="mesh" rgba="1 1 1 1" mesh="right_ring_proximal_link" />
                              <body name="right_ring_distal_link" pos="0 0 0.035">
                                <inertial pos="0.0036609 5.57858e-08 0.0190714" quat="0.705755 0.0436974 0.0436974 0.705755" mass="0.011" diaginertia="9.70588e-07 9.499e-07 1.07356e-07" />
                                <joint name="right_ring_distal_joint" pos="0 0 0" axis="0 1 0" range="0 1.63" actuatorfrcrange="-2 2" />
                                <geom type="mesh" rgba="1 1 1 1" mesh="right_ring_distal_link" />
                                <geom pos="0.0154392 0 0.0260561" quat="0.971858 0 0.235566 0" type="mesh" rgba="1 1 1 1" mesh="right_ring_touch_link" />
                              </body>
                            </body>
                            <body name="right_pinky_proximal_link" pos="-0.0023566 -0.029366 0.078694" quat="0.992245 0.052387 0.0771065 0.0822136">
                              <inertial pos="-0.00213212 7.75039e-06 0.0160672" quat="0.999803 0.000555178 0.0198191 0.000562874" mass="0.009" diaginertia="1.97745e-07 1.82023e-07 8.19805e-08" />
                              <joint name="right_pinky_proximal_joint" pos="0 0 0" axis="0 1 0" range="0 1.41" actuatorfrcrange="-2 2" />
                              <geom type="mesh" rgba="1 1 1 1" mesh="right_pinky_proximal_link" />
                              <body name="right_pinky_distal_link" pos="0 0 0.029">
                                <inertial pos="0.00314681 -1.62934e-07 0.0154194" quat="0.705039 0.0540499 0.0540411 0.705038" mass="0.011" diaginertia="5.74716e-07 5.72915e-07 7.05144e-08" />
                                <joint name="right_pinky_distal_joint" pos="0 0 0" axis="0 1 0" range="0 1.63" actuatorfrcrange="-2 2" />
                                <geom type="mesh" rgba="1 1 1 1" mesh="right_pinky_distal_link" />
                                <geom pos="0.01401 0 0.021124" quat="0.971859 0 0.235565 0" type="mesh" rgba="1 1 1 1" mesh="right_pinky_touch_link" />
                              </body>
                            </body>
                          </body>
                        </body>
                      </body>
                    </body>
                  </body>
                </body>
              </body>
            </body>
          </body>
        </body>
      </body>
    </body>
  </worldbody>
</mujoco>
